Workbook

Sheet PRENOTAZIONI
A1: PRENOTAZIONI 2026
A2: IN | B2: OUT | C2: Notti | D2: CASA | E2: Ospite | F2: N. Ospiti | G2: Canale | H2: Prezzo | I2: ADR | J2: Comm. OTA | K2: Pagamento | L2: City Tax | M2: % Matteo | N2: Costo Pulizia | O2: Chi Pulisce | P2: Kit+Lav. | Q2: Rimborso | R2: NOTE | S2: #Sotto la Q | T2: LEGENDA | U2: #Casa Letiz | V2: #Casa nel B | W2: #Via San Ro | X2: #Via Cavour | Y2: #Miramare | Z2: #Agantonio | AA2: #Casa Bella | AB2: #Casa Verde | AC2: #Casa Nicol | AD2: #White Cott | AE2: #Villa Nell
A3: 46026 | B3: 46028 | C3: =IF(A3<>"",B3-A3,"") -> 2 | D3: Sotto la Quercia | E3: Matteo Locaputo | F3: 2 ad | G3: booking.com | H3: 223.64 | I3: =IF(AND(H3<>"",C3<>"",C3<>0),H3/C3,"") -> 111.82 | J3: =IF(AND(ISNUMBER(SEARCH("booking",G3)),OR(D3="Via San Rocco",D3="Via Cavour")),H3*0.165,IF(ISNUMBER(SEARCH("airbnb",G3)),H3*0.155,IF(ISNUMBER(SEARCH("booking",G3)),H3*0.15,""))) -> 33.546 | K3: VISA | L3: 4 | M3: =IF(H3<>"",H3*0.25,"") -> 55.91 | N3: 0 | O3: Matteo | P3: 10.38 | S3: =IF(AND($D3="Sotto la Quercia",$G3<>""),ROW(),"") -> 3 | T3: Booking.com | U3: =IF(AND($D3="Casa Letizia",$G3<>""),ROW(),"") | V3: =IF(AND($D3="Casa nel Borgo",$G3<>""),ROW(),"") | W3: =IF(AND($D3="Via San Rocco",$G3<>""),ROW(),"") | X3: =IF(AND($D3="Via Cavour",$G3<>""),ROW(),"") | Y3: =IF(AND($D3="Miramare",$G3<>""),ROW(),"") | Z3: =IF(AND($D3="Agantonio",$G3<>""),ROW(),"") | AA3: =IF(AND($D3="Casa Bella Gialla",$G3<>""),ROW(),"") | AB3: =IF(AND($D3="Casa Verde Oliva",$G3<>""),ROW(),"") | AC3: =IF(AND($D3="Casa Nicola",$G3<>""),ROW(),"") | AD3: =IF(AND($D3="White Cottage",$G3<>""),ROW(),"") | AE3: =IF(AND($D3="Villa Nella",$G3<>""),ROW(),"") | AF3: =IF(AND($D3="Villa Elena",$G3<>""),ROW(),"") | AG3: =IF(AND($D3="Sotto la Quercia",$G3=""),ROW(),"") | AH3: =IF(AND($D3="Villa Elena",$G3=""),ROW(),"") | AI3: =IF(AND($D3="Casa Letizia",$G3=""),ROW(),"") | AJ3: =IF(AND($D3="Casa nel Borgo",$G3=""),ROW(),"") | AK3: =IF(AND($D3="Via San Rocco",$G3=""),ROW(),"") | AL3: =IF(AND($D3="Via Cavour",$G3=""),ROW(),"") | AM3: =IF(AND($D3="Miramare",$G3=""),ROW(),"") | AN3: =IF(AND($D3="Agantonio",$G3=""),ROW(),"") | AO3: =IF(AND($D3="Casa Bella Gialla",$G3=""),ROW(),"") | AP3: =IF(AND($D3="Casa Verde Oliva",$G3=""),ROW(),"") | AQ3: =IF(AND($D3="Casa Nicola",$G3=""),ROW(),"") | AR3: =IF(AND($D3="White Cottage",$G3=""),ROW(),"") | AS3: =IF(AND($D3="Villa Nella",$G3=""),ROW(),"") | AT3: =IF(AND($D3="Nel Cuore di Lanciano",$G3<>""),ROW(),"") | AU3: =IF(AND($D3="Nel Cuore di Lanciano",$G3=""),ROW(),"")
A4: 46029 | B4: 46052 | C4: =IF(A4<>"",B4-A4,"") -> 23 | D4: Casa nel Borgo | E4: Filomena Adduocchio | F4: 1 ad | H4: 300 | I4: =IF(AND(H4<>"",C4<>"",C4<>0),H4/C4,"") -> 13.043478 | J4: 0 | K4: contanti | M4: =IF(H4<>"",H4*0.25,"") -> 75 | N4: 15 | O4: DIANA | P4: 10.38 | S4: =IF(AND($D4="Sotto la Quercia",$G4<>""),ROW(),"") | T4: Airbnb | U4: =IF(AND($D4="Casa Letizia",$G4<>""),ROW(),"") | V4: =IF(AND($D4="Casa nel Borgo",$G4<>""),ROW(),"") | W4: =IF(AND($D4="Via San Rocco",$G4<>""),ROW(),"") | X4: =IF(AND($D4="Via Cavour",$G4<>""),ROW(),"") | Y4: =IF(AND($D4="Miramare",$G4<>""),ROW(),"") | Z4: =IF(AND($D4="Agantonio",$G4<>""),ROW(),"") | AA4: =IF(AND($D4="Casa Bella Gialla",$G4<>""),ROW(),"") | AB4: =IF(AND($D4="Casa Verde Oliva",$G4<>""),ROW(),"") | AC4: =IF(AND($D4="Casa Nicola",$G4<>""),ROW(),"") | AD4: =IF(AND($D4="White Cottage",$G4<>""),ROW(),"") | AE4: =IF(AND($D4="Villa Nella",$G4<>""),ROW(),"") | AF4: =IF(AND($D4="Villa Elena",$G4<>""),ROW(),"") | AG4: =IF(AND($D4="Sotto la Quercia",$G4=""),ROW(),"") | AH4: =IF(AND($D4="Villa Elena",$G4=""),ROW(),"") | AI4: =IF(AND($D4="Casa Letizia",$G4=""),ROW(),"") | AJ4: =IF(AND($D4="Casa nel Borgo",$G4=""),ROW(),"") -> 4 | AK4: =IF(AND($D4="Via San Rocco",$G4=""),ROW(),"") | AL4: =IF(AND($D4="Via Cavour",$G4=""),ROW(),"") | AM4: =IF(AND($D4="Miramare",$G4=""),ROW(),"") | AN4: =IF(AND($D4="Agantonio",$G4=""),ROW(),"") | AO4: =IF(AND($D4="Casa Bella Gialla",$G4=""),ROW(),"") | AP4: =IF(AND($D4="Casa Verde Oliva",$G4=""),ROW(),"") | AQ4: =IF(AND($D4="Casa Nicola",$G4=""),ROW(),"") | AR4: =IF(AND($D4="White Cottage",$G4=""),ROW(),"") | AS4: =IF(AND($D4="Villa Nella",$G4=""),ROW(),"") | AT4: =IF(AND($D4="Nel Cuore di Lanciano",$G4<>""),ROW(),"") | AU4: =IF(AND($D4="Nel Cuore di Lanciano",$G4=""),ROW(),"")
A5: 46038 | B5: 46040 | C5: =IF(A5<>"",B5-A5,"") -> 2 | D5: Villa Elena | E5: Giovanni Simone | F5: 4 ad | G5: diretta | H5: 200 | I5: =IF(AND(H5<>"",C5<>"",C5<>0),H5/C5,"") -> 100 | J5: 0 | K5: MASTER | L5: 8 | M5: =IF(H5<>"",H5*0.25,"") -> 50 | N5: 15 | O5: DIANA | P5: 22.24 | S5: =IF(AND($D5="Sotto la Quercia",$G5<>""),ROW(),"") | T5: Diretta | U5: =IF(AND($D5="Casa Letizia",$G5<>""),ROW(),"") | V5: =IF(AND($D5="Casa nel Borgo",$G5<>""),ROW(),"") | W5: =IF(AND($D5="Via San Rocco",$G5<>""),ROW(),"") | X5: =IF(AND($D5="Via Cavour",$G5<>""),ROW(),"") | Y5: =IF(AND($D5="Miramare",$G5<>""),ROW(),"") | Z5: =IF(AND($D5="Agantonio",$G5<>""),ROW(),"") | AA5: =IF(AND($D5="Casa Bella Gialla",$G5<>""),ROW(),"") | AB5: =IF(AND($D5="Casa Verde Oliva",$G5<>""),ROW(),"") | AC5: =IF(AND($D5="Casa Nicola",$G5<>""),ROW(),"") | AD5: =IF(AND($D5="White Cottage",$G5<>""),ROW(),"") | AE5: =IF(AND($D5="Villa Nella",$G5<>""),ROW(),"") | AF5: =IF(AND($D5="Villa Elena",$G5<>""),ROW(),"") -> 5 | AG5: =IF(AND($D5="Sotto la Quercia",$G5=""),ROW(),"") | AH5: =IF(AND($D5="Villa Elena",$G5=""),ROW(),"") | AI5: =IF(AND($D5="Casa Letizia",$G5=""),ROW(),"") | AJ5: =IF(AND($D5="Casa nel Borgo",$G5=""),ROW(),"") | AK5: =IF(AND($D5="Via San Rocco",$G5=""),ROW(),"") | AL5: =IF(AND($D5="Via Cavour",$G5=""),ROW(),"") | AM5: =IF(AND($D5="Miramare",$G5=""),ROW(),"") | AN5: =IF(AND($D5="Agantonio",$G5=""),ROW(),"") | AO5: =IF(AND($D5="Casa Bella Gialla",$G5=""),ROW(),"") | AP5: =IF(AND($D5="Casa Verde Oliva",$G5=""),ROW(),"") | AQ5: =IF(AND($D5="Casa Nicola",$G5=""),ROW(),"") | AR5: =IF(AND($D5="White Cottage",$G5=""),ROW(),"") | AS5: =IF(AND($D5="Villa Nella",$G5=""),ROW(),"") | AT5: =IF(AND($D5="Nel Cuore di Lanciano",$G5<>""),ROW(),"") | AU5: =IF(AND($D5="Nel Cuore di Lanciano",$G5=""),ROW(),"")
A6: 46053 | B6: 46055 | C6: =IF(A6<>"",B6-A6,"") -> 2 | D6: Via San Rocco | E6: Maria Proietti | F6: 2 ad | G6: booking.com | H6: 192.3 | I6: =IF(AND(H6<>"",C6<>"",C6<>0),H6/C6,"") -> 96.15 | J6: =IF(AND(ISNUMBER(SEARCH("booking",G6)),OR(D6="Via San Rocco",D6="Via Cavour")),H6*0.165,IF(ISNUMBER(SEARCH("airbnb",G6)),H6*0.155,IF(ISNUMBER(SEARCH("booking",G6)),H6*0.15,""))) -> 31.7295 | L6: 4 | M6: =IF(H6<>"",H6*0.1,"") -> 19.23 | S6: =IF(AND($D6="Sotto la Quercia",$G6<>""),ROW(),"") | T6: Via San Rocco/Cavour | U6: =IF(AND($D6="Casa Letizia",$G6<>""),ROW(),"") | V6: =IF(AND($D6="Casa nel Borgo",$G6<>""),ROW(),"") | W6: =IF(AND($D6="Via San Rocco",$G6<>""),ROW(),"") -> 6 | X6: =IF(AND($D6="Via Cavour",$G6<>""),ROW(),"") | Y6: =IF(AND($D6="Miramare",$G6<>""),ROW(),"") | Z6: =IF(AND($D6="Agantonio",$G6<>""),ROW(),"") | AA6: =IF(AND($D6="Casa Bella Gialla",$G6<>""),ROW(),"") | AB6: =IF(AND($D6="Casa Verde Oliva",$G6<>""),ROW(),"") | AC6: =IF(AND($D6="Casa Nicola",$G6<>""),ROW(),"") | AD6: =IF(AND($D6="White Cottage",$G6<>""),ROW(),"") | AE6: =IF(AND($D6="Villa Nella",$G6<>""),ROW(),"") | AF6: =IF(AND($D6="Villa Elena",$G6<>""),ROW(),"") | AG6: =IF(AND($D6="Sotto la Quercia",$G6=""),ROW(),"") | AH6: =IF(AND($D6="Villa Elena",$G6=""),ROW(),"") | AI6: =IF(AND($D6="Casa Letizia",$G6=""),ROW(),"") | AJ6: =IF(AND($D6="Casa nel Borgo",$G6=""),ROW(),"") | AK6: =IF(AND($D6="Via San Rocco",$G6=""),ROW(),"") | AL6: =IF(AND($D6="Via Cavour",$G6=""),ROW(),"") | AM6: =IF(AND($D6="Miramare",$G6=""),ROW(),"") | AN6: =IF(AND($D6="Agantonio",$G6=""),ROW(),"") | AO6: =IF(AND($D6="Casa Bella Gialla",$G6=""),ROW(),"") | AP6: =IF(AND($D6="Casa Verde Oliva",$G6=""),ROW(),"") | AQ6: =IF(AND($D6="Casa Nicola",$G6=""),ROW(),"") | AR6: =IF(AND($D6="White Cottage",$G6=""),ROW(),"") | AS6: =IF(AND($D6="Villa Nella",$G6=""),ROW(),"") | AT6: =IF(AND($D6="Nel Cuore di Lanciano",$G6<>""),ROW(),"") | AU6: =IF(AND($D6="Nel Cuore di Lanciano",$G6=""),ROW(),"")
A7: 46055 | B7: 46064 | C7: =IF(A7<>"",B7-A7,"") -> 9 | D7: Casa nel Borgo | E7: Filomena Adduocchio | F7: 1 ad | H7: 300 | I7: =IF(AND(H7<>"",C7<>"",C7<>0),H7/C7,"") -> 33.333333 | J7: 0 | K7: contanti | M7: =IF(H7<>"",H7*0.25,"") -> 75 | N7: 15 | O7: DIANA | P7: 10.38 | S7: =IF(AND($D7="Sotto la Quercia",$G7<>""),ROW(),"") | T7: NON RIMBORSABILE | U7: =IF(AND($D7="Casa Letizia",$G7<>""),ROW(),"") | V7: =IF(AND($D7="Casa nel Borgo",$G7<>""),ROW(),"") | W7: =IF(AND($D7="Via San Rocco",$G7<>""),ROW(),"") | X7: =IF(AND($D7="Via Cavour",$G7<>""),ROW(),"") | Y7: =IF(AND($D7="Miramare",$G7<>""),ROW(),"") | Z7: =IF(AND($D7="Agantonio",$G7<>""),ROW(),"") | AA7: =IF(AND($D7="Casa Bella Gialla",$G7<>""),ROW(),"") | AB7: =IF(AND($D7="Casa Verde Oliva",$G7<>""),ROW(),"") | AC7: =IF(AND($D7="Casa Nicola",$G7<>""),ROW(),"") | AD7: =IF(AND($D7="White Cottage",$G7<>""),ROW(),"") | AE7: =IF(AND($D7="Villa Nella",$G7<>""),ROW(),"") | AF7: =IF(AND($D7="Villa Elena",$G7<>""),ROW(),"") | AG7: =IF(AND($D7="Sotto la Quercia",$G7=""),ROW(),"") | AH7: =IF(AND($D7="Villa Elena",$G7=""),ROW(),"") | AI7: =IF(AND($D7="Casa Letizia",$G7=""),ROW(),"") | AJ7: =IF(AND($D7="Casa nel Borgo",$G7=""),ROW(),"") -> 7 | AK7: =IF(AND($D7="Via San Rocco",$G7=""),ROW(),"") | AL7: =IF(AND($D7="Via Cavour",$G7=""),ROW(),"") | AM7: =IF(AND($D7="Miramare",$G7=""),ROW(),"") | AN7: =IF(AND($D7="Agantonio",$G7=""),ROW(),"") | AO7: =IF(AND($D7="Casa Bella Gialla",$G7=""),ROW(),"") | AP7: =IF(AND($D7="Casa Verde Oliva",$G7=""),ROW(),"") | AQ7: =IF(AND($D7="Casa Nicola",$G7=""),ROW(),"") | AR7: =IF(AND($D7="White Cottage",$G7=""),ROW(),"") | AS7: =IF(AND($D7="Villa Nella",$G7=""),ROW(),"") | AT7: =IF(AND($D7="Nel Cuore di Lanciano",$G7<>""),ROW(),"") | AU7: =IF(AND($D7="Nel Cuore di Lanciano",$G7=""),ROW(),"")
A8: 46056 | B8: 46058 | C8: =IF(A8<>"",B8-A8,"") -> 2 | D8: Villa Elena | E8: Monia Cardo | F8: 1 ad | H8: 162 | I8: =IF(AND(H8<>"",C8<>"",C8<>0),H8/C8,"") -> 81 | J8: 0 | K8: contanti | M8: =IF(H8<>"",H8*0.25,"") -> 40.5 | N8: 20 | O8: DIANA | P8: 10.38 | S8: =IF(AND($D8="Sotto la Quercia",$G8<>""),ROW(),"") | T8: =IF($D8="Villa Elena",COUNTIF($D$3:$D8,"Villa Elena"),"") -> 2 | U8: =IF(AND($D8="Casa Letizia",$G8<>""),ROW(),"") | V8: =IF(AND($D8="Casa nel Borgo",$G8<>""),ROW(),"") | W8: =IF(AND($D8="Via San Rocco",$G8<>""),ROW(),"") | X8: =IF(AND($D8="Via Cavour",$G8<>""),ROW(),"") | Y8: =IF(AND($D8="Miramare",$G8<>""),ROW(),"") | Z8: =IF(AND($D8="Agantonio",$G8<>""),ROW(),"") | AA8: =IF(AND($D8="Casa Bella Gialla",$G8<>""),ROW(),"") | AB8: =IF(AND($D8="Casa Verde Oliva",$G8<>""),ROW(),"") | AC8: =IF(AND($D8="Casa Nicola",$G8<>""),ROW(),"") | AD8: =IF(AND($D8="White Cottage",$G8<>""),ROW(),"") | AE8: =IF(AND($D8="Villa Nella",$G8<>""),ROW(),"") | AF8: =IF(AND($D8="Villa Elena",$G8<>""),ROW(),"") | AG8: =IF(AND($D8="Sotto la Quercia",$G8=""),ROW(),"") | AH8: =IF(AND($D8="Villa Elena",$G8=""),ROW(),"") -> 8 | AI8: =IF(AND($D8="Casa Letizia",$G8=""),ROW(),"") | AJ8: =IF(AND($D8="Casa nel Borgo",$G8=""),ROW(),"") | AK8: =IF(AND($D8="Via San Rocco",$G8=""),ROW(),"") | AL8: =IF(AND($D8="Via Cavour",$G8=""),ROW(),"") | AM8: =IF(AND($D8="Miramare",$G8=""),ROW(),"") | AN8: =IF(AND($D8="Agantonio",$G8=""),ROW(),"") | AO8: =IF(AND($D8="Casa Bella Gialla",$G8=""),ROW(),"") | AP8: =IF(AND($D8="Casa Verde Oliva",$G8=""),ROW(),"") | AQ8: =IF(AND($D8="Casa Nicola",$G8=""),ROW(),"") | AR8: =IF(AND($D8="White Cottage",$G8=""),ROW(),"") | AS8: =IF(AND($D8="Villa Nella",$G8=""),ROW(),"") | AT8: =IF(AND($D8="Nel Cuore di Lanciano",$G8<>""),ROW(),"") | AU8: =IF(AND($D8="Nel Cuore di Lanciano",$G8=""),ROW(),"")
A9: 46066 | B9: 46072 | C9: =IF(A9<>"",B9-A9,"") -> 6 | D9: Casa nel Borgo | E9: Cornelia Bruckner | F9: 2 ad | G9: booking.com | H9: 475.13 | I9: =IF(AND(H9<>"",C9<>"",C9<>0),H9/C9,"") -> 79.188333 | J9: =IF(AND(ISNUMBER(SEARCH("booking",G9)),OR(D9="Via San Rocco",D9="Via Cavour")),H9*0.165,IF(ISNUMBER(SEARCH("airbnb",G9)),H9*0.155,IF(ISNUMBER(SEARCH("booking",G9)),H9*0.15,""))) -> 71.2695 | K9: VISA | L9: 4 | M9: =IF(H9<>"",H9*0.25,"") -> 118.7825 | N9: 30 | O9: DUSHA | P9: 10.38 | R9: NON RIMBORSABILE | S9: =IF(AND($D9="Sotto la Quercia",$G9<>""),ROW(),"") | T9: =IF($D9="Villa Elena",COUNTIF($D$3:$D9,"Villa Elena"),"") | U9: =IF(AND($D9="Casa Letizia",$G9<>""),ROW(),"") | V9: =IF(AND($D9="Casa nel Borgo",$G9<>""),ROW(),"") -> 9 | W9: =IF(AND($D9="Via San Rocco",$G9<>""),ROW(),"") | X9: =IF(AND($D9="Via Cavour",$G9<>""),ROW(),"") | Y9: =IF(AND($D9="Miramare",$G9<>""),ROW(),"") | Z9: =IF(AND($D9="Agantonio",$G9<>""),ROW(),"") | AA9: =IF(AND($D9="Casa Bella Gialla",$G9<>""),ROW(),"") | AB9: =IF(AND($D9="Casa Verde Oliva",$G9<>""),ROW(),"") | AC9: =IF(AND($D9="Casa Nicola",$G9<>""),ROW(),"") | AD9: =IF(AND($D9="White Cottage",$G9<>""),ROW(),"") | AE9: =IF(AND($D9="Villa Nella",$G9<>""),ROW(),"") | AF9: =IF(AND($D9="Villa Elena",$G9<>""),ROW(),"") | AG9: =IF(AND($D9="Sotto la Quercia",$G9=""),ROW(),"") | AH9: =IF(AND($D9="Villa Elena",$G9=""),ROW(),"") | AI9: =IF(AND($D9="Casa Letizia",$G9=""),ROW(),"") | AJ9: =IF(AND($D9="Casa nel Borgo",$G9=""),ROW(),"") | AK9: =IF(AND($D9="Via San Rocco",$G9=""),ROW(),"") | AL9: =IF(AND($D9="Via Cavour",$G9=""),ROW(),"") | AM9: =IF(AND($D9="Miramare",$G9=""),ROW(),"") | AN9: =IF(AND($D9="Agantonio",$G9=""),ROW(),"") | AO9: =IF(AND($D9="Casa Bella Gialla",$G9=""),ROW(),"") | AP9: =IF(AND($D9="Casa Verde Oliva",$G9=""),ROW(),"") | AQ9: =IF(AND($D9="Casa Nicola",$G9=""),ROW(),"") | AR9: =IF(AND($D9="White Cottage",$G9=""),ROW(),"") | AS9: =IF(AND($D9="Villa Nella",$G9=""),ROW(),"") | AT9: =IF(AND($D9="Nel Cuore di Lanciano",$G9<>""),ROW(),"") | AU9: =IF(AND($D9="Nel Cuore di Lanciano",$G9=""),ROW(),"")
A10: 46072 | B10: 46089 | C10: =IF(A10<>"",B10-A10,"") -> 17 | D10: Casa nel Borgo | E10: Filomena Adduocchio | F10: 1 ad | H10: 300 | I10: =IF(AND(H10<>"",C10<>"",C10<>0),H10/C10,"") -> 17.647059 | J10: 0 | K10: contanti | M10: =IF(H10<>"",H10*0.25,"") -> 75 | N10: 20 | O10: DUSHA | P10: 10.38 | S10: =IF(AND($D10="Sotto la Quercia",$G10<>""),ROW(),"") | T10: =IF($D10="Villa Elena",COUNTIF($D$3:$D10,"Villa Elena"),"") | U10: =IF(AND($D10="Casa Letizia",$G10<>""),ROW(),"") | V10: =IF(AND($D10="Casa nel Borgo",$G10<>""),ROW(),"") | W10: =IF(AND($D10="Via San Rocco",$G10<>""),ROW(),"") | X10: =IF(AND($D10="Via Cavour",$G10<>""),ROW(),"") | Y10: =IF(AND($D10="Miramare",$G10<>""),ROW(),"") | Z10: =IF(AND($D10="Agantonio",$G10<>""),ROW(),"") | AA10: =IF(AND($D10="Casa Bella Gialla",$G10<>""),ROW(),"") | AB10: =IF(AND($D10="Casa Verde Oliva",$G10<>""),ROW(),"") | AC10: =IF(AND($D10="Casa Nicola",$G10<>""),ROW(),"") | AD10: =IF(AND($D10="White Cottage",$G10<>""),ROW(),"") | AE10: =IF(AND($D10="Villa Nella",$G10<>""),ROW(),"") | AF10: =IF(AND($D10="Villa Elena",$G10<>""),ROW(),"") | AG10: =IF(AND($D10="Sotto la Quercia",$G10=""),ROW(),"") | AH10: =IF(AND($D10="Villa Elena",$G10=""),ROW(),"") | AI10: =IF(AND($D10="Casa Letizia",$G10=""),ROW(),"") | AJ10: =IF(AND($D10="Casa nel Borgo",$G10=""),ROW(),"") -> 10 | AK10: =IF(AND($D10="Via San Rocco",$G10=""),ROW(),"") | AL10: =IF(AND($D10="Via Cavour",$G10=""),ROW(),"") | AM10: =IF(AND($D10="Miramare",$G10=""),ROW(),"") | AN10: =IF(AND($D10="Agantonio",$G10=""),ROW(),"") | AO10: =IF(AND($D10="Casa Bella Gialla",$G10=""),ROW(),"") | AP10: =IF(AND($D10="Casa Verde Oliva",$G10=""),ROW(),"") | AQ10: =IF(AND($D10="Casa Nicola",$G10=""),ROW(),"") | AR10: =IF(AND($D10="White Cottage",$G10=""),ROW(),"") | AS10: =IF(AND($D10="Villa Nella",$G10=""),ROW(),"") | AT10: =IF(AND($D10="Nel Cuore di Lanciano",$G10<>""),ROW(),"") | AU10: =IF(AND($D10="Nel Cuore di Lanciano",$G10=""),ROW(),"")
A11: 46091 | B11: 46093 | C11: =IF(A11<>"",B11-A11,"") -> 2 | D11: Villa Elena | E11: Monia Cardo | F11: 1 ad | H11: 162 | I11: =IF(AND(H11<>"",C11<>"",C11<>0),H11/C11,"") -> 81 | J11: 0 | K11: contanti | M11: =IF(H11<>"",H11*0.25,"") -> 40.5 | N11: 0 | O11: MATTEO | P11: 10.38 | S11: =IF(AND($D11="Sotto la Quercia",$G11<>""),ROW(),"") | T11: =IF($D11="Villa Elena",COUNTIF($D$3:$D11,"Villa Elena"),"") -> 3 | U11: =IF(AND($D11="Casa Letizia",$G11<>""),ROW(),"") | V11: =IF(AND($D11="Casa nel Borgo",$G11<>""),ROW(),"") | W11: =IF(AND($D11="Via San Rocco",$G11<>""),ROW(),"") | X11: =IF(AND($D11="Via Cavour",$G11<>""),ROW(),"") | Y11: =IF(AND($D11="Miramare",$G11<>""),ROW(),"") | Z11: =IF(AND($D11="Agantonio",$G11<>""),ROW(),"") | AA11: =IF(AND($D11="Casa Bella Gialla",$G11<>""),ROW(),"") | AB11: =IF(AND($D11="Casa Verde Oliva",$G11<>""),ROW(),"") | AC11: =IF(AND($D11="Casa Nicola",$G11<>""),ROW(),"") | AD11: =IF(AND($D11="White Cottage",$G11<>""),ROW(),"") | AE11: =IF(AND($D11="Villa Nella",$G11<>""),ROW(),"") | AF11: =IF(AND($D11="Villa Elena",$G11<>""),ROW(),"") | AG11: =IF(AND($D11="Sotto la Quercia",$G11=""),ROW(),"") | AH11: =IF(AND($D11="Villa Elena",$G11=""),ROW(),"") -> 11 | AI11: =IF(AND($D11="Casa Letizia",$G11=""),ROW(),"") | AJ11: =IF(AND($D11="Casa nel Borgo",$G11=""),ROW(),"") | AK11: =IF(AND($D11="Via San Rocco",$G11=""),ROW(),"") | AL11: =IF(AND($D11="Via Cavour",$G11=""),ROW(),"") | AM11: =IF(AND($D11="Miramare",$G11=""),ROW(),"") | AN11: =IF(AND($D11="Agantonio",$G11=""),ROW(),"") | AO11: =IF(AND($D11="Casa Bella Gialla",$G11=""),ROW(),"") | AP11: =IF(AND($D11="Casa Verde Oliva",$G11=""),ROW(),"") | AQ11: =IF(AND($D11="Casa Nicola",$G11=""),ROW(),"") | AR11: =IF(AND($D11="White Cottage",$G11=""),ROW(),"") | AS11: =IF(AND($D11="Villa Nella",$G11=""),ROW(),"") | AT11: =IF(AND($D11="Nel Cuore di Lanciano",$G11<>""),ROW(),"") | AU11: =IF(AND($D11="Nel Cuore di Lanciano",$G11=""),ROW(),"")
A12: 46097 | B12: 46110 | C12: =IF(A12<>"",B12-A12,"") -> 13 | D12: Casa nel Borgo | E12: Filomena Adduocchio | F12: 2 ad | H12: 300 | I12: =IF(AND(H12<>"",C12<>"",C12<>0),H12/C12,"") -> 23.076923 | J12: 0 | K12: contanti | M12: =IF(H12<>"",H12*0.25,"") -> 75 | N12: 15 | O12: DIANA | P12: 10.38 | S12: =IF(AND($D12="Sotto la Quercia",$G12<>""),ROW(),"") | T12: =IF($D12="Villa Elena",COUNTIF($D$3:$D12,"Villa Elena"),"") | U12: =IF(AND($D12="Casa Letizia",$G12<>""),ROW(),"") | V12: =IF(AND($D12="Casa nel Borgo",$G12<>""),ROW(),"") | W12: =IF(AND($D12="Via San Rocco",$G12<>""),ROW(),"") | X12: =IF(AND($D12="Via Cavour",$G12<>""),ROW(),"") | Y12: =IF(AND($D12="Miramare",$G12<>""),ROW(),"") | Z12: =IF(AND($D12="Agantonio",$G12<>""),ROW(),"") | AA12: =IF(AND($D12="Casa Bella Gialla",$G12<>""),ROW(),"") | AB12: =IF(AND($D12="Casa Verde Oliva",$G12<>""),ROW(),"") | AC12: =IF(AND($D12="Casa Nicola",$G12<>""),ROW(),"") | AD12: =IF(AND($D12="White Cottage",$G12<>""),ROW(),"") | AE12: =IF(AND($D12="Villa Nella",$G12<>""),ROW(),"") | AF12: =IF(AND($D12="Villa Elena",$G12<>""),ROW(),"") | AG12: =IF(AND($D12="Sotto la Quercia",$G12=""),ROW(),"") | AH12: =IF(AND($D12="Villa Elena",$G12=""),ROW(),"") | AI12: =IF(AND($D12="Casa Letizia",$G12=""),ROW(),"") | AJ12: =IF(AND($D12="Casa nel Borgo",$G12=""),ROW(),"") -> 12 | AK12: =IF(AND($D12="Via San Rocco",$G12=""),ROW(),"") | AL12: =IF(AND($D12="Via Cavour",$G12=""),ROW(),"") | AM12: =IF(AND($D12="Miramare",$G12=""),ROW(),"") | AN12: =IF(AND($D12="Agantonio",$G12=""),ROW(),"") | AO12: =IF(AND($D12="Casa Bella Gialla",$G12=""),ROW(),"") | AP12: =IF(AND($D12="Casa Verde Oliva",$G12=""),ROW(),"") | AQ12: =IF(AND($D12="Casa Nicola",$G12=""),ROW(),"") | AR12: =IF(AND($D12="White Cottage",$G12=""),ROW(),"") | AS12: =IF(AND($D12="Villa Nella",$G12=""),ROW(),"") | AT12: =IF(AND($D12="Nel Cuore di Lanciano",$G12<>""),ROW(),"") | AU12: =IF(AND($D12="Nel Cuore di Lanciano",$G12=""),ROW(),"")
A13: 46105 | B13: 46109 | C13: =IF(A13<>"",B13-A13,"") -> 4 | D13: Via Cavour | E13: Flavia di Campli | F13: 1 ad | G13: booking.com | H13: 322.64 | I13: =IF(AND(H13<>"",C13<>"",C13<>0),H13/C13,"") -> 80.66 | J13: =IF(AND(ISNUMBER(SEARCH("booking",G13)),OR(D13="Via San Rocco",D13="Via Cavour")),H13*0.165,IF(ISNUMBER(SEARCH("airbnb",G13)),H13*0.155,IF(ISNUMBER(SEARCH("booking",G13)),H13*0.15,""))) -> 53.2356 | L13: 2 | M13: =IF(H13<>"",H13*0.1,"") -> 32.264 | S13: =IF(AND($D13="Sotto la Quercia",$G13<>""),ROW(),"") | T13: =IF($D13="Villa Elena",COUNTIF($D$3:$D13,"Villa Elena"),"") | U13: =IF(AND($D13="Casa Letizia",$G13<>""),ROW(),"") | V13: =IF(AND($D13="Casa nel Borgo",$G13<>""),ROW(),"") | W13: =IF(AND($D13="Via San Rocco",$G13<>""),ROW(),"") | X13: =IF(AND($D13="Via Cavour",$G13<>""),ROW(),"") -> 13 | Y13: =IF(AND($D13="Miramare",$G13<>""),ROW(),"") | Z13: =IF(AND($D13="Agantonio",$G13<>""),ROW(),"") | AA13: =IF(AND($D13="Casa Bella Gialla",$G13<>""),ROW(),"") | AB13: =IF(AND($D13="Casa Verde Oliva",$G13<>""),ROW(),"") | AC13: =IF(AND($D13="Casa Nicola",$G13<>""),ROW(),"") | AD13: =IF(AND($D13="White Cottage",$G13<>""),ROW(),"") | AE13: =IF(AND($D13="Villa Nella",$G13<>""),ROW(),"") | AF13: =IF(AND($D13="Villa Elena",$G13<>""),ROW(),"") | AG13: =IF(AND($D13="Sotto la Quercia",$G13=""),ROW(),"") | AH13: =IF(AND($D13="Villa Elena",$G13=""),ROW(),"") | AI13: =IF(AND($D13="Casa Letizia",$G13=""),ROW(),"") | AJ13: =IF(AND($D13="Casa nel Borgo",$G13=""),ROW(),"") | AK13: =IF(AND($D13="Via San Rocco",$G13=""),ROW(),"") | AL13: =IF(AND($D13="Via Cavour",$G13=""),ROW(),"") | AM13: =IF(AND($D13="Miramare",$G13=""),ROW(),"") | AN13: =IF(AND($D13="Agantonio",$G13=""),ROW(),"") | AO13: =IF(AND($D13="Casa Bella Gialla",$G13=""),ROW(),"") | AP13: =IF(AND($D13="Casa Verde Oliva",$G13=""),ROW(),"") | AQ13: =IF(AND($D13="Casa Nicola",$G13=""),ROW(),"") | AR13: =IF(AND($D13="White Cottage",$G13=""),ROW(),"") | AS13: =IF(AND($D13="Villa Nella",$G13=""),ROW(),"") | AT13: =IF(AND($D13="Nel Cuore di Lanciano",$G13<>""),ROW(),"") | AU13: =IF(AND($D13="Nel Cuore di Lanciano",$G13=""),ROW(),"")
A14: 46107 | B14: 46110 | C14: =IF(A14<>"",B14-A14,"") -> 3 | D14: Via San Rocco | E14: Simeno Riccomob | F14: 1 ad | G14: diretta | H14: 225 | I14: =IF(AND(H14<>"",C14<>"",C14<>0),H14/C14,"") -> 75 | J14: =IF(AND(ISNUMBER(SEARCH("booking",G14)),OR(D14="Via San Rocco",D14="Via Cavour")),H14*0.165,IF(ISNUMBER(SEARCH("airbnb",G14)),H14*0.155,IF(ISNUMBER(SEARCH("booking",G14)),H14*0.15,""))) | L14: 2 | M14: =IF(H14<>"",H14*0.1,"") -> 22.5 | S14: =IF(AND($D14="Sotto la Quercia",$G14<>""),ROW(),"") | T14: =IF($D14="Villa Elena",COUNTIF($D$3:$D14,"Villa Elena"),"") | U14: =IF(AND($D14="Casa Letizia",$G14<>""),ROW(),"") | V14: =IF(AND($D14="Casa nel Borgo",$G14<>""),ROW(),"") | W14: =IF(AND($D14="Via San Rocco",$G14<>""),ROW(),"") -> 14 | X14: =IF(AND($D14="Via Cavour",$G14<>""),ROW(),"") | Y14: =IF(AND($D14="Miramare",$G14<>""),ROW(),"") | Z14: =IF(AND($D14="Agantonio",$G14<>""),ROW(),"") | AA14: =IF(AND($D14="Casa Bella Gialla",$G14<>""),ROW(),"") | AB14: =IF(AND($D14="Casa Verde Oliva",$G14<>""),ROW(),"") | AC14: =IF(AND($D14="Casa Nicola",$G14<>""),ROW(),"") | AD14: =IF(AND($D14="White Cottage",$G14<>""),ROW(),"") | AE14: =IF(AND($D14="Villa Nella",$G14<>""),ROW(),"") | AF14: =IF(AND($D14="Villa Elena",$G14<>""),ROW(),"") | AG14: =IF(AND($D14="Sotto la Quercia",$G14=""),ROW(),"") | AH14: =IF(AND($D14="Villa Elena",$G14=""),ROW(),"") | AI14: =IF(AND($D14="Casa Letizia",$G14=""),ROW(),"") | AJ14: =IF(AND($D14="Casa nel Borgo",$G14=""),ROW(),"") | AK14: =IF(AND($D14="Via San Rocco",$G14=""),ROW(),"") | AL14: =IF(AND($D14="Via Cavour",$G14=""),ROW(),"") | AM14: =IF(AND($D14="Miramare",$G14=""),ROW(),"") | AN14: =IF(AND($D14="Agantonio",$G14=""),ROW(),"") | AO14: =IF(AND($D14="Casa Bella Gialla",$G14=""),ROW(),"") | AP14: =IF(AND($D14="Casa Verde Oliva",$G14=""),ROW(),"") | AQ14: =IF(AND($D14="Casa Nicola",$G14=""),ROW(),"") | AR14: =IF(AND($D14="White Cottage",$G14=""),ROW(),"") | AS14: =IF(AND($D14="Villa Nella",$G14=""),ROW(),"") | AT14: =IF(AND($D14="Nel Cuore di Lanciano",$G14<>""),ROW(),"") | AU14: =IF(AND($D14="Nel Cuore di Lanciano",$G14=""),ROW(),"")
A15: 46108 | B15: 46111 | C15: =IF(A15<>"",B15-A15,"") -> 3 | D15: Casa Bella Gialla | E15: Domenico Martorella | F15: 2 ad 1 b | G15: booking.com | H15: 202.65 | I15: =IF(AND(H15<>"",C15<>"",C15<>0),H15/C15,"") -> 67.55 | J15: =IF(AND(ISNUMBER(SEARCH("booking",G15)),OR(D15="Via San Rocco",D15="Via Cavour")),H15*0.165,IF(ISNUMBER(SEARCH("airbnb",G15)),H15*0.155,IF(ISNUMBER(SEARCH("booking",G15)),H15*0.15,""))) -> 30.3975 | K15: MASTER | L15: 4 | M15: =IF(H15<>"",H15*0.25,"") -> 50.6625 | N15: 30 | O15: DIANA | P15: 16.31 | S15: =IF(AND($D15="Sotto la Quercia",$G15<>""),ROW(),"") | T15: =IF($D15="Villa Elena",COUNTIF($D$3:$D15,"Villa Elena"),"") | U15: =IF(AND($D15="Casa Letizia",$G15<>""),ROW(),"") | V15: =IF(AND($D15="Casa nel Borgo",$G15<>""),ROW(),"") | W15: =IF(AND($D15="Via San Rocco",$G15<>""),ROW(),"") | X15: =IF(AND($D15="Via Cavour",$G15<>""),ROW(),"") | Y15: =IF(AND($D15="Miramare",$G15<>""),ROW(),"") | Z15: =IF(AND($D15="Agantonio",$G15<>""),ROW(),"") | AA15: =IF(AND($D15="Casa Bella Gialla",$G15<>""),ROW(),"") -> 15 | AB15: =IF(AND($D15="Casa Verde Oliva",$G15<>""),ROW(),"") | AC15: =IF(AND($D15="Casa Nicola",$G15<>""),ROW(),"") | AD15: =IF(AND($D15="White Cottage",$G15<>""),ROW(),"") | AE15: =IF(AND($D15="Villa Nella",$G15<>""),ROW(),"") | AF15: =IF(AND($D15="Villa Elena",$G15<>""),ROW(),"") | AG15: =IF(AND($D15="Sotto la Quercia",$G15=""),ROW(),"") | AH15: =IF(AND($D15="Villa Elena",$G15=""),ROW(),"") | AI15: =IF(AND($D15="Casa Letizia",$G15=""),ROW(),"") | AJ15: =IF(AND($D15="Casa nel Borgo",$G15=""),ROW(),"") | AK15: =IF(AND($D15="Via San Rocco",$G15=""),ROW(),"") | AL15: =IF(AND($D15="Via Cavour",$G15=""),ROW(),"") | AM15: =IF(AND($D15="Miramare",$G15=""),ROW(),"") | AN15: =IF(AND($D15="Agantonio",$G15=""),ROW(),"") | AO15: =IF(AND($D15="Casa Bella Gialla",$G15=""),ROW(),"") | AP15: =IF(AND($D15="Casa Verde Oliva",$G15=""),ROW(),"") | AQ15: =IF(AND($D15="Casa Nicola",$G15=""),ROW(),"") | AR15: =IF(AND($D15="White Cottage",$G15=""),ROW(),"") | AS15: =IF(AND($D15="Villa Nella",$G15=""),ROW(),"") | AT15: =IF(AND($D15="Nel Cuore di Lanciano",$G15<>""),ROW(),"") | AU15: =IF(AND($D15="Nel Cuore di Lanciano",$G15=""),ROW(),"")
A16: 46114 | B16: 46118 | C16: =IF(A16<>"",B16-A16,"") -> 4 | D16: Casa nel Borgo | E16: Tommaso Rossini | F16: 2 ad 1 b | G16: booking.com | H16: 383.08 | I16: =IF(AND(H16<>"",C16<>"",C16<>0),H16/C16,"") -> 95.77 | J16: =IF(AND(ISNUMBER(SEARCH("booking",G16)),OR(D16="Via San Rocco",D16="Via Cavour")),H16*0.165,IF(ISNUMBER(SEARCH("airbnb",G16)),H16*0.155,IF(ISNUMBER(SEARCH("booking",G16)),H16*0.15,""))) -> 57.462 | K16: BONIFICO | L16: 4 | M16: =IF(H16<>"",H16*0.25,"") -> 95.77 | N16: 20 | O16: JESSICA | P16: 16.31 | S16: =IF(AND($D16="Sotto la Quercia",$G16<>""),ROW(),"") | T16: =IF($D16="Villa Elena",COUNTIF($D$3:$D16,"Villa Elena"),"") | U16: =IF(AND($D16="Casa Letizia",$G16<>""),ROW(),"") | V16: =IF(AND($D16="Casa nel Borgo",$G16<>""),ROW(),"") -> 16 | W16: =IF(AND($D16="Via San Rocco",$G16<>""),ROW(),"") | X16: =IF(AND($D16="Via Cavour",$G16<>""),ROW(),"") | Y16: =IF(AND($D16="Miramare",$G16<>""),ROW(),"") | Z16: =IF(AND($D16="Agantonio",$G16<>""),ROW(),"") | AA16: =IF(AND($D16="Casa Bella Gialla",$G16<>""),ROW(),"") | AB16: =IF(AND($D16="Casa Verde Oliva",$G16<>""),ROW(),"") | AC16: =IF(AND($D16="Casa Nicola",$G16<>""),ROW(),"") | AD16: =IF(AND($D16="White Cottage",$G16<>""),ROW(),"") | AE16: =IF(AND($D16="Villa Nella",$G16<>""),ROW(),"") | AF16: =IF(AND($D16="Villa Elena",$G16<>""),ROW(),"") | AG16: =IF(AND($D16="Sotto la Quercia",$G16=""),ROW(),"") | AH16: =IF(AND($D16="Villa Elena",$G16=""),ROW(),"") | AI16: =IF(AND($D16="Casa Letizia",$G16=""),ROW(),"") | AJ16: =IF(AND($D16="Casa nel Borgo",$G16=""),ROW(),"") | AK16: =IF(AND($D16="Via San Rocco",$G16=""),ROW(),"") | AL16: =IF(AND($D16="Via Cavour",$G16=""),ROW(),"") | AM16: =IF(AND($D16="Miramare",$G16=""),ROW(),"") | AN16: =IF(AND($D16="Agantonio",$G16=""),ROW(),"") | AO16: =IF(AND($D16="Casa Bella Gialla",$G16=""),ROW(),"") | AP16: =IF(AND($D16="Casa Verde Oliva",$G16=""),ROW(),"") | AQ16: =IF(AND($D16="Casa Nicola",$G16=""),ROW(),"") | AR16: =IF(AND($D16="White Cottage",$G16=""),ROW(),"") | AS16: =IF(AND($D16="Villa Nella",$G16=""),ROW(),"") | AT16: =IF(AND($D16="Nel Cuore di Lanciano",$G16<>""),ROW(),"") | AU16: =IF(AND($D16="Nel Cuore di Lanciano",$G16=""),ROW(),"")
A17: 46115 | B17: 46118 | C17: =IF(A17<>"",B17-A17,"") -> 3 | D17: Agantonio | E17: Alessandro / Guido Peroni | F17: 2 ad | G17: booking.com | H17: 210.71 | I17: =IF(AND(H17<>"",C17<>"",C17<>0),H17/C17,"") -> 70.236667 | J17: =IF(AND(ISNUMBER(SEARCH("booking",G17)),OR(D17="Via San Rocco",D17="Via Cavour")),H17*0.165,IF(ISNUMBER(SEARCH("airbnb",G17)),H17*0.155,IF(ISNUMBER(SEARCH("booking",G17)),H17*0.15,""))) -> 31.6065 | K17: contanti | L17: 6 | M17: =IF(H17<>"",H17*0.25,"") -> 52.6775 | N17: 40 | O17: MARILENA | P17: 10.38 | S17: =IF(AND($D17="Sotto la Quercia",$G17<>""),ROW(),"") | T17: =IF($D17="Villa Elena",COUNTIF($D$3:$D17,"Villa Elena"),"") | U17: =IF(AND($D17="Casa Letizia",$G17<>""),ROW(),"") | V17: =IF(AND($D17="Casa nel Borgo",$G17<>""),ROW(),"") | W17: =IF(AND($D17="Via San Rocco",$G17<>""),ROW(),"") | X17: =IF(AND($D17="Via Cavour",$G17<>""),ROW(),"") | Y17: =IF(AND($D17="Miramare",$G17<>""),ROW(),"") | Z17: =IF(AND($D17="Agantonio",$G17<>""),ROW(),"") -> 17 | AA17: =IF(AND($D17="Casa Bella Gialla",$G17<>""),ROW(),"") | AB17: =IF(AND($D17="Casa Verde Oliva",$G17<>""),ROW(),"") | AC17: =IF(AND($D17="Casa Nicola",$G17<>""),ROW(),"") | AD17: =IF(AND($D17="White Cottage",$G17<>""),ROW(),"") | AE17: =IF(AND($D17="Villa Nella",$G17<>""),ROW(),"") | AF17: =IF(AND($D17="Villa Elena",$G17<>""),ROW(),"") | AG17: =IF(AND($D17="Sotto la Quercia",$G17=""),ROW(),"") | AH17: =IF(AND($D17="Villa Elena",$G17=""),ROW(),"") | AI17: =IF(AND($D17="Casa Letizia",$G17=""),ROW(),"") | AJ17: =IF(AND($D17="Casa nel Borgo",$G17=""),ROW(),"") | AK17: =IF(AND($D17="Via San Rocco",$G17=""),ROW(),"") | AL17: =IF(AND($D17="Via Cavour",$G17=""),ROW(),"") | AM17: =IF(AND($D17="Miramare",$G17=""),ROW(),"") | AN17: =IF(AND($D17="Agantonio",$G17=""),ROW(),"") | AO17: =IF(AND($D17="Casa Bella Gialla",$G17=""),ROW(),"") | AP17: =IF(AND($D17="Casa Verde Oliva",$G17=""),ROW(),"") | AQ17: =IF(AND($D17="Casa Nicola",$G17=""),ROW(),"") | AR17: =IF(AND($D17="White Cottage",$G17=""),ROW(),"") | AS17: =IF(AND($D17="Villa Nella",$G17=""),ROW(),"") | AT17: =IF(AND($D17="Nel Cuore di Lanciano",$G17<>""),ROW(),"") | AU17: =IF(AND($D17="Nel Cuore di Lanciano",$G17=""),ROW(),"")
A18: 46116 | B18: 46118 | C18: =IF(A18<>"",B18-A18,"") -> 2 | D18: Sotto la Quercia | E18: Giada Bruni | F18: 4 ad + 2 b | G18: booking.com | H18: 511.6 | I18: =IF(AND(H18<>"",C18<>"",C18<>0),H18/C18,"") -> 255.8 | J18: =IF(AND(ISNUMBER(SEARCH("booking",G18)),OR(D18="Via San Rocco",D18="Via Cavour")),H18*0.165,IF(ISNUMBER(SEARCH("airbnb",G18)),H18*0.155,IF(ISNUMBER(SEARCH("booking",G18)),H18*0.15,""))) -> 76.74 | K18: contanti | L18: 12 | M18: =IF(H18<>"",H18*0.25,"") -> 127.9 | N18: 30 | O18: RITA | P18: 38.55 | S18: =IF(AND($D18="Sotto la Quercia",$G18<>""),ROW(),"") -> 18 | T18: =IF($D18="Villa Elena",COUNTIF($D$3:$D18,"Villa Elena"),"") | U18: =IF(AND($D18="Casa Letizia",$G18<>""),ROW(),"") | V18: =IF(AND($D18="Casa nel Borgo",$G18<>""),ROW(),"") | W18: =IF(AND($D18="Via San Rocco",$G18<>""),ROW(),"") | X18: =IF(AND($D18="Via Cavour",$G18<>""),ROW(),"") | Y18: =IF(AND($D18="Miramare",$G18<>""),ROW(),"") | Z18: =IF(AND($D18="Agantonio",$G18<>""),ROW(),"") | AA18: =IF(AND($D18="Casa Bella Gialla",$G18<>""),ROW(),"") | AB18: =IF(AND($D18="Casa Verde Oliva",$G18<>""),ROW(),"") | AC18: =IF(AND($D18="Casa Nicola",$G18<>""),ROW(),"") | AD18: =IF(AND($D18="White Cottage",$G18<>""),ROW(),"") | AE18: =IF(AND($D18="Villa Nella",$G18<>""),ROW(),"") | AF18: =IF(AND($D18="Villa Elena",$G18<>""),ROW(),"") | AG18: =IF(AND($D18="Sotto la Quercia",$G18=""),ROW(),"") | AH18: =IF(AND($D18="Villa Elena",$G18=""),ROW(),"") | AI18: =IF(AND($D18="Casa Letizia",$G18=""),ROW(),"") | AJ18: =IF(AND($D18="Casa nel Borgo",$G18=""),ROW(),"") | AK18: =IF(AND($D18="Via San Rocco",$G18=""),ROW(),"") | AL18: =IF(AND($D18="Via Cavour",$G18=""),ROW(),"") | AM18: =IF(AND($D18="Miramare",$G18=""),ROW(),"") | AN18: =IF(AND($D18="Agantonio",$G18=""),ROW(),"") | AO18: =IF(AND($D18="Casa Bella Gialla",$G18=""),ROW(),"") | AP18: =IF(AND($D18="Casa Verde Oliva",$G18=""),ROW(),"") | AQ18: =IF(AND($D18="Casa Nicola",$G18=""),ROW(),"") | AR18: =IF(AND($D18="White Cottage",$G18=""),ROW(),"") | AS18: =IF(AND($D18="Villa Nella",$G18=""),ROW(),"") | AT18: =IF(AND($D18="Nel Cuore di Lanciano",$G18<>""),ROW(),"") | AU18: =IF(AND($D18="Nel Cuore di Lanciano",$G18=""),ROW(),"")
A19: 46116 | B19: 46119 | C19: =IF(A19<>"",B19-A19,"") -> 3 | D19: Via San Rocco | E19: Sharon Ilaria Zangirolami | F19: 2 ad 1 b | G19: booking.com | H19: 328.22 | I19: =IF(AND(H19<>"",C19<>"",C19<>0),H19/C19,"") -> 109.40667 | J19: =IF(AND(ISNUMBER(SEARCH("booking",G19)),OR(D19="Via San Rocco",D19="Via Cavour")),H19*0.165,IF(ISNUMBER(SEARCH("airbnb",G19)),H19*0.155,IF(ISNUMBER(SEARCH("booking",G19)),H19*0.15,""))) -> 54.1563 | L19: 4 | M19: =IF(H19<>"",H19*0.1,"") -> 32.822 | S19: =IF(AND($D19="Sotto la Quercia",$G19<>""),ROW(),"") | T19: =IF($D19="Villa Elena",COUNTIF($D$3:$D19,"Villa Elena"),"") | U19: =IF(AND($D19="Casa Letizia",$G19<>""),ROW(),"") | V19: =IF(AND($D19="Casa nel Borgo",$G19<>""),ROW(),"") | W19: =IF(AND($D19="Via San Rocco",$G19<>""),ROW(),"") -> 19 | X19: =IF(AND($D19="Via Cavour",$G19<>""),ROW(),"") | Y19: =IF(AND($D19="Miramare",$G19<>""),ROW(),"") | Z19: =IF(AND($D19="Agantonio",$G19<>""),ROW(),"") | AA19: =IF(AND($D19="Casa Bella Gialla",$G19<>""),ROW(),"") | AB19: =IF(AND($D19="Casa Verde Oliva",$G19<>""),ROW(),"") | AC19: =IF(AND($D19="Casa Nicola",$G19<>""),ROW(),"") | AD19: =IF(AND($D19="White Cottage",$G19<>""),ROW(),"") | AE19: =IF(AND($D19="Villa Nella",$G19<>""),ROW(),"") | AF19: =IF(AND($D19="Villa Elena",$G19<>""),ROW(),"") | AG19: =IF(AND($D19="Sotto la Quercia",$G19=""),ROW(),"") | AH19: =IF(AND($D19="Villa Elena",$G19=""),ROW(),"") | AI19: =IF(AND($D19="Casa Letizia",$G19=""),ROW(),"") | AJ19: =IF(AND($D19="Casa nel Borgo",$G19=""),ROW(),"") | AK19: =IF(AND($D19="Via San Rocco",$G19=""),ROW(),"") | AL19: =IF(AND($D19="Via Cavour",$G19=""),ROW(),"") | AM19: =IF(AND($D19="Miramare",$G19=""),ROW(),"") | AN19: =IF(AND($D19="Agantonio",$G19=""),ROW(),"") | AO19: =IF(AND($D19="Casa Bella Gialla",$G19=""),ROW(),"") | AP19: =IF(AND($D19="Casa Verde Oliva",$G19=""),ROW(),"") | AQ19: =IF(AND($D19="Casa Nicola",$G19=""),ROW(),"") | AR19: =IF(AND($D19="White Cottage",$G19=""),ROW(),"") | AS19: =IF(AND($D19="Villa Nella",$G19=""),ROW(),"") | AT19: =IF(AND($D19="Nel Cuore di Lanciano",$G19<>""),ROW(),"") | AU19: =IF(AND($D19="Nel Cuore di Lanciano",$G19=""),ROW(),"")
A20: 46123 | B20: 46136 | C20: =IF(A20<>"",B20-A20,"") -> 13 | D20: Via San Rocco | E20: Concetta D'Orsogna | F20: 2 ad | G20: diretta | H20: 1105 | I20: =IF(AND(H20<>"",C20<>"",C20<>0),H20/C20,"") -> 85 | J20: =IF(AND(ISNUMBER(SEARCH("booking",G20)),OR(D20="Via San Rocco",D20="Via Cavour")),H20*0.165,IF(ISNUMBER(SEARCH("airbnb",G20)),H20*0.155,IF(ISNUMBER(SEARCH("booking",G20)),H20*0.15,""))) | L20: 4 | M20: =IF(H20<>"",H20*0.1,"") -> 110.5 | S20: =IF(AND($D20="Sotto la Quercia",$G20<>""),ROW(),"") | T20: =IF($D20="Villa Elena",COUNTIF($D$3:$D20,"Villa Elena"),"") | U20: =IF(AND($D20="Casa Letizia",$G20<>""),ROW(),"") | V20: =IF(AND($D20="Casa nel Borgo",$G20<>""),ROW(),"") | W20: =IF(AND($D20="Via San Rocco",$G20<>""),ROW(),"") -> 20 | X20: =IF(AND($D20="Via Cavour",$G20<>""),ROW(),"") | Y20: =IF(AND($D20="Miramare",$G20<>""),ROW(),"") | Z20: =IF(AND($D20="Agantonio",$G20<>""),ROW(),"") | AA20: =IF(AND($D20="Casa Bella Gialla",$G20<>""),ROW(),"") | AB20: =IF(AND($D20="Casa Verde Oliva",$G20<>""),ROW(),"") | AC20: =IF(AND($D20="Casa Nicola",$G20<>""),ROW(),"") | AD20: =IF(AND($D20="White Cottage",$G20<>""),ROW(),"") | AE20: =IF(AND($D20="Villa Nella",$G20<>""),ROW(),"") | AF20: =IF(AND($D20="Villa Elena",$G20<>""),ROW(),"") | AG20: =IF(AND($D20="Sotto la Quercia",$G20=""),ROW(),"") | AH20: =IF(AND($D20="Villa Elena",$G20=""),ROW(),"") | AI20: =IF(AND($D20="Casa Letizia",$G20=""),ROW(),"") | AJ20: =IF(AND($D20="Casa nel Borgo",$G20=""),ROW(),"") | AK20: =IF(AND($D20="Via San Rocco",$G20=""),ROW(),"") | AL20: =IF(AND($D20="Via Cavour",$G20=""),ROW(),"") | AM20: =IF(AND($D20="Miramare",$G20=""),ROW(),"") | AN20: =IF(AND($D20="Agantonio",$G20=""),ROW(),"") | AO20: =IF(AND($D20="Casa Bella Gialla",$G20=""),ROW(),"") | AP20: =IF(AND($D20="Casa Verde Oliva",$G20=""),ROW(),"") | AQ20: =IF(AND($D20="Casa Nicola",$G20=""),ROW(),"") | AR20: =IF(AND($D20="White Cottage",$G20=""),ROW(),"") | AS20: =IF(AND($D20="Villa Nella",$G20=""),ROW(),"") | AT20: =IF(AND($D20="Nel Cuore di Lanciano",$G20<>""),ROW(),"") | AU20: =IF(AND($D20="Nel Cuore di Lanciano",$G20=""),ROW(),"")
A21: 46124 | B21: 46128 | C21: =IF(A21<>"",B21-A21,"") -> 4 | D21: Via Cavour | E21: Luca D'Orsogna | F21: 2 ad + 3 b | G21: diretta | H21: 420 | I21: =IF(AND(H21<>"",C21<>"",C21<>0),H21/C21,"") -> 105 | J21: =IF(AND(ISNUMBER(SEARCH("booking",G21)),OR(D21="Via San Rocco",D21="Via Cavour")),H21*0.165,IF(ISNUMBER(SEARCH("airbnb",G21)),H21*0.155,IF(ISNUMBER(SEARCH("booking",G21)),H21*0.15,""))) | L21: 4 | M21: =IF(H21<>"",H21*0.1,"") -> 42 | S21: =IF(AND($D21="Sotto la Quercia",$G21<>""),ROW(),"") | T21: =IF($D21="Villa Elena",COUNTIF($D$3:$D21,"Villa Elena"),"") | U21: =IF(AND($D21="Casa Letizia",$G21<>""),ROW(),"") | V21: =IF(AND($D21="Casa nel Borgo",$G21<>""),ROW(),"") | W21: =IF(AND($D21="Via San Rocco",$G21<>""),ROW(),"") | X21: =IF(AND($D21="Via Cavour",$G21<>""),ROW(),"") -> 21 | Y21: =IF(AND($D21="Miramare",$G21<>""),ROW(),"") | Z21: =IF(AND($D21="Agantonio",$G21<>""),ROW(),"") | AA21: =IF(AND($D21="Casa Bella Gialla",$G21<>""),ROW(),"") | AB21: =IF(AND($D21="Casa Verde Oliva",$G21<>""),ROW(),"") | AC21: =IF(AND($D21="Casa Nicola",$G21<>""),ROW(),"") | AD21: =IF(AND($D21="White Cottage",$G21<>""),ROW(),"") | AE21: =IF(AND($D21="Villa Nella",$G21<>""),ROW(),"") | AF21: =IF(AND($D21="Villa Elena",$G21<>""),ROW(),"") | AG21: =IF(AND($D21="Sotto la Quercia",$G21=""),ROW(),"") | AH21: =IF(AND($D21="Villa Elena",$G21=""),ROW(),"") | AI21: =IF(AND($D21="Casa Letizia",$G21=""),ROW(),"") | AJ21: =IF(AND($D21="Casa nel Borgo",$G21=""),ROW(),"") | AK21: =IF(AND($D21="Via San Rocco",$G21=""),ROW(),"") | AL21: =IF(AND($D21="Via Cavour",$G21=""),ROW(),"") | AM21: =IF(AND($D21="Miramare",$G21=""),ROW(),"") | AN21: =IF(AND($D21="Agantonio",$G21=""),ROW(),"") | AO21: =IF(AND($D21="Casa Bella Gialla",$G21=""),ROW(),"") | AP21: =IF(AND($D21="Casa Verde Oliva",$G21=""),ROW(),"") | AQ21: =IF(AND($D21="Casa Nicola",$G21=""),ROW(),"") | AR21: =IF(AND($D21="White Cottage",$G21=""),ROW(),"") | AS21: =IF(AND($D21="Villa Nella",$G21=""),ROW(),"") | AT21: =IF(AND($D21="Nel Cuore di Lanciano",$G21<>""),ROW(),"") | AU21: =IF(AND($D21="Nel Cuore di Lanciano",$G21=""),ROW(),"")
A22: 46129 | B22: 46131 | C22: =IF(A22<>"",B22-A22,"") -> 2 | D22: Sotto la Quercia | E22: Raffaele Guasco | F22: 4 ad | G22: booking.com | H22: 388.92 | I22: =IF(AND(H22<>"",C22<>"",C22<>0),H22/C22,"") -> 194.46 | J22: =IF(AND(ISNUMBER(SEARCH("booking",G22)),OR(D22="Via San Rocco",D22="Via Cavour")),H22*0.165,IF(ISNUMBER(SEARCH("airbnb",G22)),H22*0.155,IF(ISNUMBER(SEARCH("booking",G22)),H22*0.15,""))) -> 58.338 | K22: MASTER | L22: 0 | M22: =IF(H22<>"",H22*0.25,"") -> 97.23 | O22: NESSUNO | R22: NON RIMBORSABILE - pagamento effettuato 30-01. NO SHOW | S22: =IF(AND($D22="Sotto la Quercia",$G22<>""),ROW(),"") -> 22 | T22: =IF($D22="Villa Elena",COUNTIF($D$3:$D22,"Villa Elena"),"") | U22: =IF(AND($D22="Casa Letizia",$G22<>""),ROW(),"") | V22: =IF(AND($D22="Casa nel Borgo",$G22<>""),ROW(),"") | W22: =IF(AND($D22="Via San Rocco",$G22<>""),ROW(),"") | X22: =IF(AND($D22="Via Cavour",$G22<>""),ROW(),"") | Y22: =IF(AND($D22="Miramare",$G22<>""),ROW(),"") | Z22: =IF(AND($D22="Agantonio",$G22<>""),ROW(),"") | AA22: =IF(AND($D22="Casa Bella Gialla",$G22<>""),ROW(),"") | AB22: =IF(AND($D22="Casa Verde Oliva",$G22<>""),ROW(),"") | AC22: =IF(AND($D22="Casa Nicola",$G22<>""),ROW(),"") | AD22: =IF(AND($D22="White Cottage",$G22<>""),ROW(),"") | AE22: =IF(AND($D22="Villa Nella",$G22<>""),ROW(),"") | AF22: =IF(AND($D22="Villa Elena",$G22<>""),ROW(),"") | AG22: =IF(AND($D22="Sotto la Quercia",$G22=""),ROW(),"") | AH22: =IF(AND($D22="Villa Elena",$G22=""),ROW(),"") | AI22: =IF(AND($D22="Casa Letizia",$G22=""),ROW(),"") | AJ22: =IF(AND($D22="Casa nel Borgo",$G22=""),ROW(),"") | AK22: =IF(AND($D22="Via San Rocco",$G22=""),ROW(),"") | AL22: =IF(AND($D22="Via Cavour",$G22=""),ROW(),"") | AM22: =IF(AND($D22="Miramare",$G22=""),ROW(),"") | AN22: =IF(AND($D22="Agantonio",$G22=""),ROW(),"") | AO22: =IF(AND($D22="Casa Bella Gialla",$G22=""),ROW(),"") | AP22: =IF(AND($D22="Casa Verde Oliva",$G22=""),ROW(),"") | AQ22: =IF(AND($D22="Casa Nicola",$G22=""),ROW(),"") | AR22: =IF(AND($D22="White Cottage",$G22=""),ROW(),"") | AS22: =IF(AND($D22="Villa Nella",$G22=""),ROW(),"") | AT22: =IF(AND($D22="Nel Cuore di Lanciano",$G22<>""),ROW(),"") | AU22: =IF(AND($D22="Nel Cuore di Lanciano",$G22=""),ROW(),"")
A23: 46129 | B23: 46132 | C23: =IF(A23<>"",B23-A23,"") -> 3 | D23: Villa Elena | E23: Luca Ferrari | F23: 3 ad | G23: diretta | H23: 300 | I23: =IF(AND(H23<>"",C23<>"",C23<>0),H23/C23,"") -> 100 | J23: 0 | L23: 6 | M23: =IF(H23<>"",H23*0.25,"") -> 75 | N23: 20 | O23: JESSICA | P23: 19 | S23: =IF(AND($D23="Sotto la Quercia",$G23<>""),ROW(),"") | T23: =IF($D23="Villa Elena",COUNTIF($D$3:$D23,"Villa Elena"),"") -> 4 | U23: =IF(AND($D23="Casa Letizia",$G23<>""),ROW(),"") | V23: =IF(AND($D23="Casa nel Borgo",$G23<>""),ROW(),"") | W23: =IF(AND($D23="Via San Rocco",$G23<>""),ROW(),"") | X23: =IF(AND($D23="Via Cavour",$G23<>""),ROW(),"") | Y23: =IF(AND($D23="Miramare",$G23<>""),ROW(),"") | Z23: =IF(AND($D23="Agantonio",$G23<>""),ROW(),"") | AA23: =IF(AND($D23="Casa Bella Gialla",$G23<>""),ROW(),"") | AB23: =IF(AND($D23="Casa Verde Oliva",$G23<>""),ROW(),"") | AC23: =IF(AND($D23="Casa Nicola",$G23<>""),ROW(),"") | AD23: =IF(AND($D23="White Cottage",$G23<>""),ROW(),"") | AE23: =IF(AND($D23="Villa Nella",$G23<>""),ROW(),"") | AF23: =IF(AND($D23="Villa Elena",$G23<>""),ROW(),"") -> 23 | AG23: =IF(AND($D23="Sotto la Quercia",$G23=""),ROW(),"") | AH23: =IF(AND($D23="Villa Elena",$G23=""),ROW(),"") | AI23: =IF(AND($D23="Casa Letizia",$G23=""),ROW(),"") | AJ23: =IF(AND($D23="Casa nel Borgo",$G23=""),ROW(),"") | AK23: =IF(AND($D23="Via San Rocco",$G23=""),ROW(),"") | AL23: =IF(AND($D23="Via Cavour",$G23=""),ROW(),"") | AM23: =IF(AND($D23="Miramare",$G23=""),ROW(),"") | AN23: =IF(AND($D23="Agantonio",$G23=""),ROW(),"") | AO23: =IF(AND($D23="Casa Bella Gialla",$G23=""),ROW(),"") | AP23: =IF(AND($D23="Casa Verde Oliva",$G23=""),ROW(),"") | AQ23: =IF(AND($D23="Casa Nicola",$G23=""),ROW(),"") | AR23: =IF(AND($D23="White Cottage",$G23=""),ROW(),"") | AS23: =IF(AND($D23="Villa Nella",$G23=""),ROW(),"") | AT23: =IF(AND($D23="Nel Cuore di Lanciano",$G23<>""),ROW(),"") | AU23: =IF(AND($D23="Nel Cuore di Lanciano",$G23=""),ROW(),"")
A24: 46134 | B24: 46136 | C24: =IF(A24<>"",B24-A24,"") -> 2 | D24: Casa nel Borgo | E24: Marina Alves | F24: 1 ad | G24: Airbnb | H24: 196 | I24: =IF(AND(H24<>"",C24<>"",C24<>0),H24/C24,"") -> 98 | J24: =IF(AND(ISNUMBER(SEARCH("booking",G24)),OR(D24="Via San Rocco",D24="Via Cavour")),H24*0.165,IF(ISNUMBER(SEARCH("airbnb",G24)),H24*0.155,IF(ISNUMBER(SEARCH("booking",G24)),H24*0.15,""))) -> 30.38 | K24: Airbnb | L24: 2 | M24: =IF(H24<>"",H24*0.25,"") -> 49 | N24: 10 | O24: JESSICA | P24: 8.27 | S24: =IF(AND($D24="Sotto la Quercia",$G24<>""),ROW(),"") | T24: =IF($D24="Villa Elena",COUNTIF($D$3:$D24,"Villa Elena"),"") | U24: =IF(AND($D24="Casa Letizia",$G24<>""),ROW(),"") | V24: =IF(AND($D24="Casa nel Borgo",$G24<>""),ROW(),"") -> 24 | W24: =IF(AND($D24="Via San Rocco",$G24<>""),ROW(),"") | X24: =IF(AND($D24="Via Cavour",$G24<>""),ROW(),"") | Y24: =IF(AND($D24="Miramare",$G24<>""),ROW(),"") | Z24: =IF(AND($D24="Agantonio",$G24<>""),ROW(),"") | AA24: =IF(AND($D24="Casa Bella Gialla",$G24<>""),ROW(),"") | AB24: =IF(AND($D24="Casa Verde Oliva",$G24<>""),ROW(),"") | AC24: =IF(AND($D24="Casa Nicola",$G24<>""),ROW(),"") | AD24: =IF(AND($D24="White Cottage",$G24<>""),ROW(),"") | AE24: =IF(AND($D24="Villa Nella",$G24<>""),ROW(),"") | AF24: =IF(AND($D24="Villa Elena",$G24<>""),ROW(),"") | AG24: =IF(AND($D24="Sotto la Quercia",$G24=""),ROW(),"") | AH24: =IF(AND($D24="Villa Elena",$G24=""),ROW(),"") | AI24: =IF(AND($D24="Casa Letizia",$G24=""),ROW(),"") | AJ24: =IF(AND($D24="Casa nel Borgo",$G24=""),ROW(),"") | AK24: =IF(AND($D24="Via San Rocco",$G24=""),ROW(),"") | AL24: =IF(AND($D24="Via Cavour",$G24=""),ROW(),"") | AM24: =IF(AND($D24="Miramare",$G24=""),ROW(),"") | AN24: =IF(AND($D24="Agantonio",$G24=""),ROW(),"") | AO24: =IF(AND($D24="Casa Bella Gialla",$G24=""),ROW(),"") | AP24: =IF(AND($D24="Casa Verde Oliva",$G24=""),ROW(),"") | AQ24: =IF(AND($D24="Casa Nicola",$G24=""),ROW(),"") | AR24: =IF(AND($D24="White Cottage",$G24=""),ROW(),"") | AS24: =IF(AND($D24="Villa Nella",$G24=""),ROW(),"") | AT24: =IF(AND($D24="Nel Cuore di Lanciano",$G24<>""),ROW(),"") | AU24: =IF(AND($D24="Nel Cuore di Lanciano",$G24=""),ROW(),"")
A25: 46142 | B25: 46145 | C25: =IF(A25<>"",B25-A25,"") -> 3 | D25: Agantonio | E25: Martina Pieri | F25: 1 ad 2 b | G25: booking.com | H25: 218 | I25: =IF(AND(H25<>"",C25<>"",C25<>0),H25/C25,"") -> 72.666667 | J25: =IF(AND(ISNUMBER(SEARCH("booking",G25)),OR(D25="Via San Rocco",D25="Via Cavour")),H25*0.165,IF(ISNUMBER(SEARCH("airbnb",G25)),H25*0.155,IF(ISNUMBER(SEARCH("booking",G25)),H25*0.15,""))) -> 32.7 | K25: MASTER | L25: 3 | M25: =IF(H25<>"",H25*0.25,"") -> 54.5 | N25: 20 | O25: MARILENA | P25: 16.14 | S25: =IF(AND($D25="Sotto la Quercia",$G25<>""),ROW(),"") | T25: =IF($D25="Villa Elena",COUNTIF($D$3:$D25,"Villa Elena"),"") | U25: =IF(AND($D25="Casa Letizia",$G25<>""),ROW(),"") | V25: =IF(AND($D25="Casa nel Borgo",$G25<>""),ROW(),"") | W25: =IF(AND($D25="Via San Rocco",$G25<>""),ROW(),"") | X25: =IF(AND($D25="Via Cavour",$G25<>""),ROW(),"") | Y25: =IF(AND($D25="Miramare",$G25<>""),ROW(),"") | Z25: =IF(AND($D25="Agantonio",$G25<>""),ROW(),"") -> 25 | AA25: =IF(AND($D25="Casa Bella Gialla",$G25<>""),ROW(),"") | AB25: =IF(AND($D25="Casa Verde Oliva",$G25<>""),ROW(),"") | AC25: =IF(AND($D25="Casa Nicola",$G25<>""),ROW(),"") | AD25: =IF(AND($D25="White Cottage",$G25<>""),ROW(),"") | AE25: =IF(AND($D25="Villa Nella",$G25<>""),ROW(),"") | AF25: =IF(AND($D25="Villa Elena",$G25<>""),ROW(),"") | AG25: =IF(AND($D25="Sotto la Quercia",$G25=""),ROW(),"") | AH25: =IF(AND($D25="Villa Elena",$G25=""),ROW(),"") | AI25: =IF(AND($D25="Casa Letizia",$G25=""),ROW(),"") | AJ25: =IF(AND($D25="Casa nel Borgo",$G25=""),ROW(),"") | AK25: =IF(AND($D25="Via San Rocco",$G25=""),ROW(),"") | AL25: =IF(AND($D25="Via Cavour",$G25=""),ROW(),"") | AM25: =IF(AND($D25="Miramare",$G25=""),ROW(),"") | AN25: =IF(AND($D25="Agantonio",$G25=""),ROW(),"") | AO25: =IF(AND($D25="Casa Bella Gialla",$G25=""),ROW(),"") | AP25: =IF(AND($D25="Casa Verde Oliva",$G25=""),ROW(),"") | AQ25: =IF(AND($D25="Casa Nicola",$G25=""),ROW(),"") | AR25: =IF(AND($D25="White Cottage",$G25=""),ROW(),"") | AS25: =IF(AND($D25="Villa Nella",$G25=""),ROW(),"") | AT25: =IF(AND($D25="Nel Cuore di Lanciano",$G25<>""),ROW(),"") | AU25: =IF(AND($D25="Nel Cuore di Lanciano",$G25=""),ROW(),"")
A26: 46142 | B26: 46148 | C26: =IF(A26<>"",B26-A26,"") -> 6 | D26: Sotto la Quercia | E26: Karatina Svitekova | F26: 3 ad | G26: diretta | H26: 900 | I26: =IF(AND(H26<>"",C26<>"",C26<>0),H26/C26,"") -> 150 | J26: 0 | K26: VISA | L26: 6 | M26: =IF(H26<>"",H26*0.25,"") -> 225 | N26: 50 | O26: RITA | P26: 19.93 | R26: preparare due matrimoniali + 1 singolo | S26: =IF(AND($D26="Sotto la Quercia",$G26<>""),ROW(),"") -> 26 | T26: =IF($D26="Villa Elena",COUNTIF($D$3:$D26,"Villa Elena"),"") | U26: =IF(AND($D26="Casa Letizia",$G26<>""),ROW(),"") | V26: =IF(AND($D26="Casa nel Borgo",$G26<>""),ROW(),"") | W26: =IF(AND($D26="Via San Rocco",$G26<>""),ROW(),"") | X26: =IF(AND($D26="Via Cavour",$G26<>""),ROW(),"") | Y26: =IF(AND($D26="Miramare",$G26<>""),ROW(),"") | Z26: =IF(AND($D26="Agantonio",$G26<>""),ROW(),"") | AA26: =IF(AND($D26="Casa Bella Gialla",$G26<>""),ROW(),"") | AB26: =IF(AND($D26="Casa Verde Oliva",$G26<>""),ROW(),"") | AC26: =IF(AND($D26="Casa Nicola",$G26<>""),ROW(),"") | AD26: =IF(AND($D26="White Cottage",$G26<>""),ROW(),"") | AE26: =IF(AND($D26="Villa Nella",$G26<>""),ROW(),"") | AF26: =IF(AND($D26="Villa Elena",$G26<>""),ROW(),"") | AG26: =IF(AND($D26="Sotto la Quercia",$G26=""),ROW(),"") | AH26: =IF(AND($D26="Villa Elena",$G26=""),ROW(),"") | AI26: =IF(AND($D26="Casa Letizia",$G26=""),ROW(),"") | AJ26: =IF(AND($D26="Casa nel Borgo",$G26=""),ROW(),"") | AK26: =IF(AND($D26="Via San Rocco",$G26=""),ROW(),"") | AL26: =IF(AND($D26="Via Cavour",$G26=""),ROW(),"") | AM26: =IF(AND($D26="Miramare",$G26=""),ROW(),"") | AN26: =IF(AND($D26="Agantonio",$G26=""),ROW(),"") | AO26: =IF(AND($D26="Casa Bella Gialla",$G26=""),ROW(),"") | AP26: =IF(AND($D26="Casa Verde Oliva",$G26=""),ROW(),"") | AQ26: =IF(AND($D26="Casa Nicola",$G26=""),ROW(),"") | AR26: =IF(AND($D26="White Cottage",$G26=""),ROW(),"") | AS26: =IF(AND($D26="Villa Nella",$G26=""),ROW(),"") | AT26: =IF(AND($D26="Nel Cuore di Lanciano",$G26<>""),ROW(),"") | AU26: =IF(AND($D26="Nel Cuore di Lanciano",$G26=""),ROW(),"")
A27: 46152 | B27: 46157 | C27: =IF(A27<>"",B27-A27,"") -> 5 | D27: Via San Rocco | E27: Korkrum kerri | F27: 2 ad | G27: booking.com | H27: 433.4 | I27: =IF(AND(H27<>"",C27<>"",C27<>0),H27/C27,"") -> 86.68 | J27: =IF(AND(ISNUMBER(SEARCH("booking",G27)),OR(D27="Via San Rocco",D27="Via Cavour")),H27*0.165,IF(ISNUMBER(SEARCH("airbnb",G27)),H27*0.155,IF(ISNUMBER(SEARCH("booking",G27)),H27*0.15,""))) -> 71.511 | L27: 4 | M27: =IF(H27<>"",H27*0.1,"") -> 43.34 | S27: =IF(AND($D27="Sotto la Quercia",$G27<>""),ROW(),"") | T27: =IF($D27="Villa Elena",COUNTIF($D$3:$D27,"Villa Elena"),"") | U27: =IF(AND($D27="Casa Letizia",$G27<>""),ROW(),"") | V27: =IF(AND($D27="Casa nel Borgo",$G27<>""),ROW(),"") | W27: =IF(AND($D27="Via San Rocco",$G27<>""),ROW(),"") -> 27 | X27: =IF(AND($D27="Via Cavour",$G27<>""),ROW(),"") | Y27: =IF(AND($D27="Miramare",$G27<>""),ROW(),"") | Z27: =IF(AND($D27="Agantonio",$G27<>""),ROW(),"") | AA27: =IF(AND($D27="Casa Bella Gialla",$G27<>""),ROW(),"") | AB27: =IF(AND($D27="Casa Verde Oliva",$G27<>""),ROW(),"") | AC27: =IF(AND($D27="Casa Nicola",$G27<>""),ROW(),"") | AD27: =IF(AND($D27="White Cottage",$G27<>""),ROW(),"") | AE27: =IF(AND($D27="Villa Nella",$G27<>""),ROW(),"") | AF27: =IF(AND($D27="Villa Elena",$G27<>""),ROW(),"") | AG27: =IF(AND($D27="Sotto la Quercia",$G27=""),ROW(),"") | AH27: =IF(AND($D27="Villa Elena",$G27=""),ROW(),"") | AI27: =IF(AND($D27="Casa Letizia",$G27=""),ROW(),"") | AJ27: =IF(AND($D27="Casa nel Borgo",$G27=""),ROW(),"") | AK27: =IF(AND($D27="Via San Rocco",$G27=""),ROW(),"") | AL27: =IF(AND($D27="Via Cavour",$G27=""),ROW(),"") | AM27: =IF(AND($D27="Miramare",$G27=""),ROW(),"") | AN27: =IF(AND($D27="Agantonio",$G27=""),ROW(),"") | AO27: =IF(AND($D27="Casa Bella Gialla",$G27=""),ROW(),"") | AP27: =IF(AND($D27="Casa Verde Oliva",$G27=""),ROW(),"") | AQ27: =IF(AND($D27="Casa Nicola",$G27=""),ROW(),"") | AR27: =IF(AND($D27="White Cottage",$G27=""),ROW(),"") | AS27: =IF(AND($D27="Villa Nella",$G27=""),ROW(),"") | AT27: =IF(AND($D27="Nel Cuore di Lanciano",$G27<>""),ROW(),"") | AU27: =IF(AND($D27="Nel Cuore di Lanciano",$G27=""),ROW(),"")
A28: 46153 | B28: 46155 | C28: =IF(A28<>"",B28-A28,"") -> 2 | D28: Villa Elena | E28: Monia Cardo | F28: 1 ad | H28: 162 | I28: =IF(AND(H28<>"",C28<>"",C28<>0),H28/C28,"") -> 81 | J28: 0 | K28: contanti | M28: =IF(H28<>"",H28*0.25,"") -> 40.5 | O28: matteo | P28: 10.38 | S28: =IF(AND($D28="Sotto la Quercia",$G28<>""),ROW(),"") | T28: =IF($D28="Villa Elena",COUNTIF($D$3:$D28,"Villa Elena"),"") -> 5 | U28: =IF(AND($D28="Casa Letizia",$G28<>""),ROW(),"") | V28: =IF(AND($D28="Casa nel Borgo",$G28<>""),ROW(),"") | W28: =IF(AND($D28="Via San Rocco",$G28<>""),ROW(),"") | X28: =IF(AND($D28="Via Cavour",$G28<>""),ROW(),"") | Y28: =IF(AND($D28="Miramare",$G28<>""),ROW(),"") | Z28: =IF(AND($D28="Agantonio",$G28<>""),ROW(),"") | AA28: =IF(AND($D28="Casa Bella Gialla",$G28<>""),ROW(),"") | AB28: =IF(AND($D28="Casa Verde Oliva",$G28<>""),ROW(),"") | AC28: =IF(AND($D28="Casa Nicola",$G28<>""),ROW(),"") | AD28: =IF(AND($D28="White Cottage",$G28<>""),ROW(),"") | AE28: =IF(AND($D28="Villa Nella",$G28<>""),ROW(),"") | AF28: =IF(AND($D28="Villa Elena",$G28<>""),ROW(),"") | AG28: =IF(AND($D28="Sotto la Quercia",$G28=""),ROW(),"") | AH28: =IF(AND($D28="Villa Elena",$G28=""),ROW(),"") -> 28 | AI28: =IF(AND($D28="Casa Letizia",$G28=""),ROW(),"") | AJ28: =IF(AND($D28="Casa nel Borgo",$G28=""),ROW(),"") | AK28: =IF(AND($D28="Via San Rocco",$G28=""),ROW(),"") | AL28: =IF(AND($D28="Via Cavour",$G28=""),ROW(),"") | AM28: =IF(AND($D28="Miramare",$G28=""),ROW(),"") | AN28: =IF(AND($D28="Agantonio",$G28=""),ROW(),"") | AO28: =IF(AND($D28="Casa Bella Gialla",$G28=""),ROW(),"") | AP28: =IF(AND($D28="Casa Verde Oliva",$G28=""),ROW(),"") | AQ28: =IF(AND($D28="Casa Nicola",$G28=""),ROW(),"") | AR28: =IF(AND($D28="White Cottage",$G28=""),ROW(),"") | AS28: =IF(AND($D28="Villa Nella",$G28=""),ROW(),"") | AT28: =IF(AND($D28="Nel Cuore di Lanciano",$G28<>""),ROW(),"") | AU28: =IF(AND($D28="Nel Cuore di Lanciano",$G28=""),ROW(),"")
A29: 46162 | B29: 46165 | C29: =IF(A29<>"",B29-A29,"") -> 3 | D29: Agantonio | E29: Enrico Minante | F29: 1 ad | G29: booking.com | H29: 173.8 | I29: =IF(AND(H29<>"",C29<>"",C29<>0),H29/C29,"") -> 57.933333 | J29: 29.55 | K29: MASTER | L29: 3 | M29: =IF(H29<>"",H29*0.25,"") -> 43.45 | N29: 20 | O29: MARILENA | P29: 10.38 | S29: =IF(AND($D29="Sotto la Quercia",$G29<>""),ROW(),"") | T29: =IF($D29="Villa Elena",COUNTIF($D$3:$D29,"Villa Elena"),"") | U29: =IF(AND($D29="Casa Letizia",$G29<>""),ROW(),"") | V29: =IF(AND($D29="Casa nel Borgo",$G29<>""),ROW(),"") | W29: =IF(AND($D29="Via San Rocco",$G29<>""),ROW(),"") | X29: =IF(AND($D29="Via Cavour",$G29<>""),ROW(),"") | Y29: =IF(AND($D29="Miramare",$G29<>""),ROW(),"") | Z29: =IF(AND($D29="Agantonio",$G29<>""),ROW(),"") -> 29 | AA29: =IF(AND($D29="Casa Bella Gialla",$G29<>""),ROW(),"") | AB29: =IF(AND($D29="Casa Verde Oliva",$G29<>""),ROW(),"") | AC29: =IF(AND($D29="Casa Nicola",$G29<>""),ROW(),"") | AD29: =IF(AND($D29="White Cottage",$G29<>""),ROW(),"") | AE29: =IF(AND($D29="Villa Nella",$G29<>""),ROW(),"") | AF29: =IF(AND($D29="Villa Elena",$G29<>""),ROW(),"") | AG29: =IF(AND($D29="Sotto la Quercia",$G29=""),ROW(),"") | AH29: =IF(AND($D29="Villa Elena",$G29=""),ROW(),"") | AI29: =IF(AND($D29="Casa Letizia",$G29=""),ROW(),"") | AJ29: =IF(AND($D29="Casa nel Borgo",$G29=""),ROW(),"") | AK29: =IF(AND($D29="Via San Rocco",$G29=""),ROW(),"") | AL29: =IF(AND($D29="Via Cavour",$G29=""),ROW(),"") | AM29: =IF(AND($D29="Miramare",$G29=""),ROW(),"") | AN29: =IF(AND($D29="Agantonio",$G29=""),ROW(),"") | AO29: =IF(AND($D29="Casa Bella Gialla",$G29=""),ROW(),"") | AP29: =IF(AND($D29="Casa Verde Oliva",$G29=""),ROW(),"") | AQ29: =IF(AND($D29="Casa Nicola",$G29=""),ROW(),"") | AR29: =IF(AND($D29="White Cottage",$G29=""),ROW(),"") | AS29: =IF(AND($D29="Villa Nella",$G29=""),ROW(),"") | AT29: =IF(AND($D29="Nel Cuore di Lanciano",$G29<>""),ROW(),"") | AU29: =IF(AND($D29="Nel Cuore di Lanciano",$G29=""),ROW(),"")
A30: 46170 | B30: 46172 | C30: =IF(A30<>"",B30-A30,"") -> 2 | D30: Via San Rocco | E30: Mirella Bonomelli | F30: 2 ad | G30: booking.com | H30: 214.78 | I30: =IF(AND(H30<>"",C30<>"",C30<>0),H30/C30,"") -> 107.39 | J30: =IF(AND(ISNUMBER(SEARCH("booking",G30)),OR(D30="Via San Rocco",D30="Via Cavour")),H30*0.165,IF(ISNUMBER(SEARCH("airbnb",G30)),H30*0.155,IF(ISNUMBER(SEARCH("booking",G30)),H30*0.15,""))) -> 35.4387 | L30: 4 | M30: =IF(H30<>"",H30*0.1,"") -> 21.478 | S30: =IF(AND($D30="Sotto la Quercia",$G30<>""),ROW(),"") | T30: =IF($D30="Villa Elena",COUNTIF($D$3:$D30,"Villa Elena"),"") | U30: =IF(AND($D30="Casa Letizia",$G30<>""),ROW(),"") | V30: =IF(AND($D30="Casa nel Borgo",$G30<>""),ROW(),"") | W30: =IF(AND($D30="Via San Rocco",$G30<>""),ROW(),"") -> 30 | X30: =IF(AND($D30="Via Cavour",$G30<>""),ROW(),"") | Y30: =IF(AND($D30="Miramare",$G30<>""),ROW(),"") | Z30: =IF(AND($D30="Agantonio",$G30<>""),ROW(),"") | AA30: =IF(AND($D30="Casa Bella Gialla",$G30<>""),ROW(),"") | AB30: =IF(AND($D30="Casa Verde Oliva",$G30<>""),ROW(),"") | AC30: =IF(AND($D30="Casa Nicola",$G30<>""),ROW(),"") | AD30: =IF(AND($D30="White Cottage",$G30<>""),ROW(),"") | AE30: =IF(AND($D30="Villa Nella",$G30<>""),ROW(),"") | AF30: =IF(AND($D30="Villa Elena",$G30<>""),ROW(),"") | AG30: =IF(AND($D30="Sotto la Quercia",$G30=""),ROW(),"") | AH30: =IF(AND($D30="Villa Elena",$G30=""),ROW(),"") | AI30: =IF(AND($D30="Casa Letizia",$G30=""),ROW(),"") | AJ30: =IF(AND($D30="Casa nel Borgo",$G30=""),ROW(),"") | AK30: =IF(AND($D30="Via San Rocco",$G30=""),ROW(),"") | AL30: =IF(AND($D30="Via Cavour",$G30=""),ROW(),"") | AM30: =IF(AND($D30="Miramare",$G30=""),ROW(),"") | AN30: =IF(AND($D30="Agantonio",$G30=""),ROW(),"") | AO30: =IF(AND($D30="Casa Bella Gialla",$G30=""),ROW(),"") | AP30: =IF(AND($D30="Casa Verde Oliva",$G30=""),ROW(),"") | AQ30: =IF(AND($D30="Casa Nicola",$G30=""),ROW(),"") | AR30: =IF(AND($D30="White Cottage",$G30=""),ROW(),"") | AS30: =IF(AND($D30="Villa Nella",$G30=""),ROW(),"") | AT30: =IF(AND($D30="Nel Cuore di Lanciano",$G30<>""),ROW(),"") | AU30: =IF(AND($D30="Nel Cuore di Lanciano",$G30=""),ROW(),"")
A31: 46172 | B31: 46175 | C31: =IF(A31<>"",B31-A31,"") -> 3 | D31: Casa Letizia | E31: Elisabetta Cappuccini | F31: 2 ad + 2 b | G31: booking.com | H31: 301.31 | I31: =IF(AND(H31<>"",C31<>"",C31<>0),H31/C31,"") -> 100.43667 | J31: =IF(AND(ISNUMBER(SEARCH("booking",G31)),OR(D31="Via San Rocco",D31="Via Cavour")),H31*0.165,IF(ISNUMBER(SEARCH("airbnb",G31)),H31*0.155,IF(ISNUMBER(SEARCH("booking",G31)),H31*0.15,""))) -> 45.1965 | K31: VISA | L31: 6 | M31: =IF(H31<>"",H31*0.25,"") -> 75.3275 | N31: 20 | O31: MARILENA | P31: 20 | S31: =IF(AND($D31="Sotto la Quercia",$G31<>""),ROW(),"") | T31: =IF($D31="Villa Elena",COUNTIF($D$3:$D31,"Villa Elena"),"") | U31: =IF(AND($D31="Casa Letizia",$G31<>""),ROW(),"") -> 31 | V31: =IF(AND($D31="Casa nel Borgo",$G31<>""),ROW(),"") | W31: =IF(AND($D31="Via San Rocco",$G31<>""),ROW(),"") | X31: =IF(AND($D31="Via Cavour",$G31<>""),ROW(),"") | Y31: =IF(AND($D31="Miramare",$G31<>""),ROW(),"") | Z31: =IF(AND($D31="Agantonio",$G31<>""),ROW(),"") | AA31: =IF(AND($D31="Casa Bella Gialla",$G31<>""),ROW(),"") | AB31: =IF(AND($D31="Casa Verde Oliva",$G31<>""),ROW(),"") | AC31: =IF(AND($D31="Casa Nicola",$G31<>""),ROW(),"") | AD31: =IF(AND($D31="White Cottage",$G31<>""),ROW(),"") | AE31: =IF(AND($D31="Villa Nella",$G31<>""),ROW(),"") | AF31: =IF(AND($D31="Villa Elena",$G31<>""),ROW(),"") | AG31: =IF(AND($D31="Sotto la Quercia",$G31=""),ROW(),"") | AH31: =IF(AND($D31="Villa Elena",$G31=""),ROW(),"") | AI31: =IF(AND($D31="Casa Letizia",$G31=""),ROW(),"") | AJ31: =IF(AND($D31="Casa nel Borgo",$G31=""),ROW(),"") | AK31: =IF(AND($D31="Via San Rocco",$G31=""),ROW(),"") | AL31: =IF(AND($D31="Via Cavour",$G31=""),ROW(),"") | AM31: =IF(AND($D31="Miramare",$G31=""),ROW(),"") | AN31: =IF(AND($D31="Agantonio",$G31=""),ROW(),"") | AO31: =IF(AND($D31="Casa Bella Gialla",$G31=""),ROW(),"") | AP31: =IF(AND($D31="Casa Verde Oliva",$G31=""),ROW(),"") | AQ31: =IF(AND($D31="Casa Nicola",$G31=""),ROW(),"") | AR31: =IF(AND($D31="White Cottage",$G31=""),ROW(),"") | AS31: =IF(AND($D31="Villa Nella",$G31=""),ROW(),"") | AT31: =IF(AND($D31="Nel Cuore di Lanciano",$G31<>""),ROW(),"") | AU31: =IF(AND($D31="Nel Cuore di Lanciano",$G31=""),ROW(),"")
